Traceback (most recent call last):
  File "C:\Users\azuka\Anaconda3\envs\jupbook\lib\site-packages\jupyter_cache\executors\utils.py", line 56, in single_nb_execution
    record_timing=False,
  File "C:\Users\azuka\Anaconda3\envs\jupbook\lib\site-packages\nbclient\client.py", line 1204, in execute
    return NotebookClient(nb=nb, resources=resources, km=km, **kwargs).execute()
  File "C:\Users\azuka\Anaconda3\envs\jupbook\lib\site-packages\nbclient\util.py", line 84, in wrapped
    return just_run(coro(*args, **kwargs))
  File "C:\Users\azuka\Anaconda3\envs\jupbook\lib\site-packages\nbclient\util.py", line 62, in just_run
    return loop.run_until_complete(coro)
  File "C:\Users\azuka\Anaconda3\envs\jupbook\lib\asyncio\base_events.py", line 587, in run_until_complete
    return future.result()
  File "C:\Users\azuka\Anaconda3\envs\jupbook\lib\site-packages\nbclient\client.py", line 664, in async_execute
    cell, index, execution_count=self.code_cells_executed + 1
  File "C:\Users\azuka\Anaconda3\envs\jupbook\lib\site-packages\nbclient\client.py", line 965, in async_execute_cell
    await self._check_raise_for_error(cell, cell_index, exec_reply)
  File "C:\Users\azuka\Anaconda3\envs\jupbook\lib\site-packages\nbclient\client.py", line 862, in _check_raise_for_error
    raise CellExecutionError.from_cell_and_msg(cell, exec_reply_content)
nbclient.exceptions.CellExecutionError: An error occurred while executing the following cell:
------------------
import plotly.io as pio
import plotly.express as px
import plotly.offline as py
import pandas as pd
import plotly.graph_objects as go

pio.renderers.default='notebook'
fig = px.scatter(df, x="sepal_width", y="sepal_length", color="species", size="sepal_length")
fig.show()
------------------

[1;31m---------------------------------------------------------------------------[0m
[1;31mNameError[0m                                 Traceback (most recent call last)
[1;32m~\AppData\Local\Temp\ipykernel_29420\873378910.py[0m in [0;36m<module>[1;34m[0m
[0;32m      6[0m [1;33m[0m[0m
[0;32m      7[0m [0mpio[0m[1;33m.[0m[0mrenderers[0m[1;33m.[0m[0mdefault[0m[1;33m=[0m[1;34m'notebook'[0m[1;33m[0m[1;33m[0m[0m
[1;32m----> 8[1;33m [0mfig[0m [1;33m=[0m [0mpx[0m[1;33m.[0m[0mscatter[0m[1;33m([0m[0mdf[0m[1;33m,[0m [0mx[0m[1;33m=[0m[1;34m"sepal_width"[0m[1;33m,[0m [0my[0m[1;33m=[0m[1;34m"sepal_length"[0m[1;33m,[0m [0mcolor[0m[1;33m=[0m[1;34m"species"[0m[1;33m,[0m [0msize[0m[1;33m=[0m[1;34m"sepal_length"[0m[1;33m)[0m[1;33m[0m[1;33m[0m[0m
[0m[0;32m      9[0m [0mfig[0m[1;33m.[0m[0mshow[0m[1;33m([0m[1;33m)[0m[1;33m[0m[1;33m[0m[0m

[1;31mNameError[0m: name 'df' is not defined
NameError: name 'df' is not defined

